 <?xml version="1.0" ?>
<robot name="ur5" xmlns:xacro="http://www.ros.org/wiki/xacro">
  <link name="world_link"/>

  <joint name="world_joint" type="fixed">
    <parent link="world_link"/>
    <child link="body_link"/>
    <origin rpy="1.570796325 0.0 1.570796325" xyz="0.0 0.0 0.0"/>
  </joint>
    
  <link name="body_link">
    <visual>
      <geometry>
        <mesh filename="meshes/visual/Body_fixed.obj"/>
      </geometry>
     </visual>
    <!-- <collision>
      <geometry>
        <mesh filename="meshes/visual/Body_fixed.obj"/>
      </geometry>
    </collision> -->
  </link>

  <!-- ================================= -->
  <!-- |          NECK JOINTS          | -->
  <!-- ================================= -->
  <joint name="neck_yaw_joint" type="revolute">
    <parent link="body_link"/>
    <child link="neck_yaw_link"/>
    <origin rpy="0 0 0" xyz="-0.03 0.915 0.34"/>
    <axis xyz="0 1 0"/>
    <limit effort="150.0" lower="-3.14159265" upper="3.14159265" velocity="3.15"/>
    <dynamics damping="0.0" friction="0.0"/>
  </joint>

  <link name="neck_yaw_link">
    <visual>
      <geometry>
        <mesh filename="meshes/visual/NeckYaw_fixed.obj"/>
      </geometry>
    </visual>
    <collision>
      <geometry>
        <mesh filename="meshes/collision/NeckYaw.stl"/>
      </geometry>
      <origin rpy="-1.570796325 0 0" xyz="0.0 0.0 0.0"/>
    </collision>
    <inertial>
      <mass value="0.1"/>
      <origin rpy="0 0 0" xyz="0.0 0.0 0.0"/>
      <inertia ixx="0.001" ixy="0.0" ixz="0.0" iyy="0.001" iyz="0.0" izz="0.001"/>
    </inertial>
  </link>

  <joint name="neck_pitch_joint" type="revolute">
    <parent link="neck_yaw_link"/>
    <child link="neck_pitch_link"/>
    <!--<origin rpy="-0.05235987755982989 0 0" xyz="-0.03 0.0 0.05"/> -->
    <origin rpy="0 0 0" xyz="-0.03 0.05 0"/>
    <axis xyz="-1 0 0"/>
    <limit effort="150.0" lower="-3.14159265" upper="3.14159265" velocity="3.15"/>
    <dynamics damping="0.0" friction="0.0"/>
  </joint>

  <link name="neck_pitch_link">
    <visual>
      <geometry>
        <mesh filename="meshes/visual/NeckPitch_fixed.obj"/>
      </geometry>
    </visual>
    <collision>
      <geometry>
        <mesh filename="meshes/collision/NeckPitch.stl"/>
      </geometry>
      <origin rpy="-1.570796325 0 0" xyz="0.0 0.0 0.0"/>
    </collision>
    <inertial>
      <mass value="0.1"/>
      <origin rpy="0 0 0" xyz="0.0 0.0 0.0"/>
      <inertia ixx="0.001" ixy="0.0" ixz="0.0" iyy="0.001" iyz="0.0" izz="0.001"/>
    </inertial>
  </link>

  <joint name="left_cam_joint" type="fixed">
    <parent link="neck_pitch_link"/>
    <child link="left_cam_link"/>
    <origin rpy="0 0 0" xyz="0.08846 0.05832 0.03125"/>
  </joint>

  <link name="left_cam_link">
  </link>

  <joint name="left_view_joint" type="fixed">
    <parent link="left_cam_link"/>
    <child link="left_view_link"/>
    <origin rpy="0 0 0" xyz="0 0 0.1"/>
  </joint>

  <link name="left_view_link">
  </link>

  <joint name="right_cam_joint" type="fixed">
    <parent link="neck_pitch_link"/>
    <child link="right_cam_link"/>
    <origin rpy="0 0 0" xyz="0.02546 0.05832 0.03125"/>
  </joint>

  <link name="right_cam_link">
  </link>

  <joint name="right_view_joint" type="fixed">
    <parent link="right_cam_link"/>
    <child link="right_view_link"/>
    <origin rpy="0 0 0" xyz="0 0 0.1"/>
  </joint>

  <link name="right_view_link">
  </link>

  <!-- ============================== -->
  <!-- |          LEFT ARM          | -->
  <!-- ============================== -->
  <joint name="l_body_joint" type="fixed">
    <parent link="body_link"/>
    <child link="l_base_link"/>
    <origin rpy="0 -0.785398163397 -1.570796325" xyz="0.2 0.93 0.0"/>
  </joint>

  <link name="l_base_link">
    <visual>
      <geometry>
        <mesh filename="meshes/visual/Base.obj"/>
      </geometry>
     </visual>
    <collision>
      <geometry>
        <mesh filename="meshes/collision/Base.stl"/>
      </geometry>
      <origin rpy="-1.570796325 0 0" xyz="0.0 0.0 0.0"/>
    </collision>
    <inertial>
      <mass value="4.0"/>
      <origin rpy="0 0 0" xyz="0.0 0.0 0.0"/>
      <inertia ixx="0.00443333156" ixy="0.0" ixz="0.0" iyy="0.00443333156" iyz="0.0" izz="0.0072"/>
    </inertial>
  </link>

  <joint name="l_shoulder_pan_joint" type="revolute">
    <parent link="l_base_link"/>
    <child link="l_shoulder_link"/>
    <origin rpy="0.0 0.0 0" xyz="0.0 0.089159 0.0"/>
    <axis xyz="0 1 0"/>
    <limit effort="150.0" lower="-3.14159265" upper="3.14159265" velocity="3.15"/>
    <dynamics damping="0.0" friction="0.0"/>
  </joint>

  <link name="l_shoulder_link">
    <visual>
      <geometry>
        <mesh filename="meshes/visual/Shoulder.obj"/>
      </geometry>
     </visual>
    <collision>
      <geometry>
        <mesh filename="meshes/collision/Shoulder.stl"/>
      </geometry>
      <origin rpy="-1.570796325 0 0" xyz="0.0 0.0 0.0"/>
    </collision>
    <inertial>
      <mass value="3.7"/>
      <origin rpy="0 0 0" xyz="0.0 0.0 0.0"/>
      <inertia ixx="0.010267495893" ixy="0.0" ixz="0.0" iyy="0.010267495893" iyz="0.0" izz="0.00666"/>
    </inertial>
  </link>
  
  <joint name="l_shoulder_lift_joint" type="revolute">
    <parent link="l_shoulder_link"/>
    <child link="l_upper_arm_link"/>
    <origin rpy="0.0 0 -1.570796325" xyz="0 0.0 -0.13585"/>
    <axis xyz="0 0 -1"/>
    <limit effort="150.0" lower="-3.14159265" upper="3.14159265" velocity="3.15"/>
    <dynamics damping="0.0" friction="0.0"/>
  </joint>
  
  <link name="l_upper_arm_link">
    <visual>
      <geometry>
        <mesh filename="meshes/visual/UpperArm.obj"/>
      </geometry>
     </visual>
    <collision>
      <geometry>
        <mesh filename="meshes/collision/UpperArm.stl"/>
      </geometry>
      <origin rpy="-1.570796325 0 0" xyz="0.0 0.0 0.0"/>
    </collision>
    <inertial>
      <mass value="8.393"/>
      <origin rpy="0 0 0" xyz="0.0 0.0 0.28"/>
      <inertia ixx="0.22689067591" ixy="0.0" ixz="0.0" iyy="0.22689067591" iyz="0.0" izz="0.0151074"/>
    </inertial>
  </link>

  <joint name="l_elbow_joint" type="revolute">
    <parent link="l_upper_arm_link"/>
    <child link="l_forearm_link"/>
    <origin rpy="0.0 0.0 0.0" xyz="0 0.425 0.1197"/>
    <axis xyz="0 0 -1"/>
    <limit effort="150.0" lower="0" upper="3.14159265" velocity="3.15"/>
    <!-- <limit effort="150.0" lower="-3.14159265" upper="3.14159265" velocity="3.15"/> -->
    <dynamics damping="0.0" friction="0.0"/>
  </joint>

  <link name="l_forearm_link">
    <visual>
      <geometry>
        <mesh filename="meshes/visual/ForeArm.obj"/>
      </geometry>
     </visual>
    <collision>
      <geometry>
        <mesh filename="meshes/collision/ForeArm.stl"/>
      </geometry>
      <origin rpy="-1.570796325 0 0" xyz="0.0 0.0 0.0"/>
    </collision>
    <inertial>
      <mass value="2.275"/>
      <origin rpy="0 0 0" xyz="0.0 0.0 0.25"/>
      <inertia ixx="0.049443313556" ixy="0.0" ixz="0.0" iyy="0.049443313556" iyz="0.0" izz="0.004095"/>
    </inertial>
  </link>

  <joint name="l_wrist_1_joint" type="revolute">
    <parent link="l_forearm_link"/>
    <child link="l_wrist_1_link"/>
    <origin rpy="0.0 0.0 -1.570796325" xyz="0.0 0.39225 0.0"/>
    <axis xyz="0 0 -1"/>
    <limit effort="28.0" lower="-3.14159265" upper="3.14159265" velocity="3.2"/>
    <dynamics damping="0.0" friction="0.0"/>
  </joint>

  <link name="l_wrist_1_link">
    <visual>
      <geometry>
        <mesh filename="meshes/visual/Wrist1.obj"/>
      </geometry>
     </visual>
    <collision>
      <geometry>
        <mesh filename="meshes/collision/Wrist1.stl"/>
      </geometry>
      <origin rpy="-1.570796325 0 0" xyz="0.0 0.0 0.0"/>
    </collision>
    <inertial>
      <mass value="1.219"/>
      <origin rpy="0 0 0" xyz="0.0 0.0 0.0"/>
      <inertia ixx="0.111172755531" ixy="0.0" ixz="0.0" iyy="0.111172755531" iyz="0.0" izz="0.21942"/>
    </inertial>
  </link>

  <joint name="l_wrist_2_joint" type="revolute">
    <parent link="l_wrist_1_link"/>
    <child link="l_wrist_2_link"/>
    <origin rpy="0.0 0.0 0.0" xyz="0.0 0.0 -0.093"/>
    <axis xyz="0 1 0"/>
    <limit effort="28.0" lower="-3.14159265" upper="3.14159265" velocity="3.2"/>
    <dynamics damping="0.0" friction="0.0"/>
  </joint>

  <link name="l_wrist_2_link">
    <visual>  
      <geometry>
        <mesh filename="meshes/visual/Wrist2.obj"/>
      </geometry>
     </visual>
    <collision>
      <geometry>
        <mesh filename="meshes/collision/Wrist2.stl"/>
      </geometry>
      <origin rpy="-1.570796325 0 0" xyz="0.0 0.0 0.0"/>
    </collision>
    <inertial>
      <mass value="1.219"/>
      <origin rpy="0 0 0" xyz="0.0 0.0 0.0"/>
      <inertia ixx="0.111172755531" ixy="0.0" ixz="0.0" iyy="0.111172755531" iyz="0.0" izz="0.21942"/>
    </inertial>
  </link>

  <joint name="l_wrist_3_joint" type="revolute">
    <parent link="l_wrist_2_link"/>
    <child link="l_wrist_3_link"/>
    <origin rpy="0.0 0.0 0.0" xyz="0.0 0.09465 0"/>
    <axis xyz="0 0 -1"/>
    <limit effort="28.0" lower="-3.14159265" upper="3.14159265" velocity="3.2"/>
    <dynamics damping="0.0" friction="0.0"/>
  </joint>

  <link name="l_wrist_3_link">
    <visual>
      <geometry>
        <mesh filename="meshes/visual/Wrist3.obj"/>
      </geometry>
     </visual>
    <collision>
      <geometry>
        <mesh filename="meshes/collision/Wrist3.stl"/>
      </geometry>
      <origin rpy="-1.570796325 0 0" xyz="0.0 0.0 0.0"/>
    </collision>
    <inertial>
      <mass value="0.1879"/>
      <origin rpy="0 0 0" xyz="0.0 0.0 0.0"/>
      <inertia ixx="0.0171364731454" ixy="0.0" ixz="0.0" iyy="0.0171364731454" iyz="0.0" izz="0.033822"/>
    </inertial>
  </link>

  <joint name="l_fixed_joint" type="fixed">
    <parent link="l_wrist_3_link"/>
    <child link="l_fixed_link"/>
    <origin rpy="0.0 1.570796325 0.0" xyz="0.0 0.0 -0.0823"/>
  </joint>

  <link name="l_fixed_link">
    <visual>
      <geometry>
        <mesh filename="meshes/visual/FixedL_fixed.obj"/>
      </geometry>
     </visual>
    <collision>
      <geometry>
        <mesh filename="meshes/collision/FixedL.stl"/>
      </geometry>
      <origin rpy="-1.570796325 0 0" xyz="0.0 0.0 0.0"/>
    </collision>
    <!-- inaccurate -->
    <inertial>
      <mass value="0.1"/>
      <origin rpy="0 0 0" xyz="0.0 0.0 0.0"/>
      <inertia ixx="0.01" ixy="0.0" ixz="0.0" iyy="0.01" iyz="0.0" izz="0.01"/>
    </inertial>
  </link>

  <joint name="l_fixed_connector_joint" type="fixed">
    <parent link="l_fixed_link"/>
    <child link="l_fixed_connector_link"/>
    <!--<origin rpy="0.0 0.0 0" xyz="0.178 -0.0405 0.0"/>-->
    <origin rpy="0.0 0.0 0" xyz="0.173 0.0 0.04150"/>
    <axis xyz="0 1 0"/>
  </joint>

  <link name="l_fixed_connector_link">
    <visual>
      <geometry>
        <mesh filename="meshes/visual/FixedConnectorL_fixed.obj"/>
      </geometry>
     </visual>
    <collision>
      <geometry>
        <mesh filename="meshes/collision/FixedConnectorL.stl"/>
      </geometry>
      <origin rpy="-1.570796325 0 0" xyz="0.0 0.0 0.0"/>
    </collision>
    <!-- inaccurate -->
    <inertial>
      <mass value="0.01"/>
      <origin rpy="0 0 0" xyz="0.0 0.0 0.0"/>
      <inertia ixx="0.001" ixy="0.0" ixz="0.0" iyy="0.001" iyz="0.0" izz="0.001"/>
    </inertial>
  </link>

  <joint name="l_fixed_sensor_joint" type="fixed">
    <parent link="l_fixed_connector_link"/>
    <child link="l_fixed_sensor_link"/>
    <origin rpy="0.0 0.0 0" xyz="0.005 0.0 -0.0010"/>
    <axis xyz="0 1 0"/>
  </joint>

  <link name="l_fixed_sensor_link">
    <visual>
      <geometry>
        <mesh filename="meshes/visual/FixedSensorL_fixed.obj"/>
      </geometry>
     </visual>
    <collision>
      <geometry>
        <mesh filename="meshes/collision/FixedSensorL.stl"/>
      </geometry>
      <origin rpy="-1.570796325 0 0" xyz="0.0 0.0 0.0"/>
    </collision>
    <!-- inaccurate -->
    <inertial>
      <mass value="0.01"/>
      <origin rpy="0 0 0" xyz="0.0 0.0 0.0"/>
      <inertia ixx="0.001" ixy="0.0" ixz="0.0" iyy="0.001" iyz="0.0" izz="0.001"/>
    </inertial>
  </link>

  <joint name="l_fixed_finger_joint" type="fixed">
    <parent link="l_fixed_sensor_link"/>
    <child link="l_fixed_finger_link"/>
    <origin rpy="0.0 0.0 0" xyz="0.023 0.0 0.0"/>
    <axis xyz="0 1 0"/>
    <limit effort="28.0" lower="-3.14159265" upper="3.14159265" velocity="3.2"/>
  </joint>

  <link name="l_fixed_finger_link">
    <visual>
      <geometry>
        <mesh filename="meshes/visual/FixedFingerL.obj"/>
      </geometry>
     </visual>
    <collision>
      <geometry>
        <mesh filename="meshes/collision/FixedFingerL.stl"/>
      </geometry>
      <origin rpy="-1.570796325 0 0" xyz="0.0 0.0 0.0"/>
    </collision>
    <!--inaccurate-->
    <inertial>
      <mass value="0.01"/>
      <origin rpy="0 0 0" xyz="0.0 0.0 0.0"/>
      <inertia ixx="0.001" ixy="0.0" ixz="0.0" iyy="0.001" iyz="0.0" izz="0.001"/>
    </inertial>
  </link>

  <joint name="l_move_joint" type="revolute">
    <parent link="l_fixed_link"/>
    <child link="l_move_link"/>
    <origin rpy="0.0 0.0 0" xyz="0.053 0.0 -0.0085"/>
    <axis xyz="0 1 0"/>
    <limit effort="28.0" lower="-3.14159265" upper="3.14159265" velocity="3.2"/>
  </joint>

  <link name="l_move_link">
    <visual>
      <geometry>
        <mesh filename="meshes/visual/MoveL_fixed.obj"/>
      </geometry>
     </visual>
    <collision>
      <geometry>
        <mesh filename="meshes/collision/MoveL.stl"/>
      </geometry>
      <origin rpy="-1.570796325 0 0" xyz="0.0 0.0 0.0"/>
    </collision>
    <!--inaccurate-->
    <inertial>
      <mass value="0.01"/>
      <origin rpy="0 0 0" xyz="0.0 0.0 0.0"/>
      <inertia ixx="0.001" ixy="0.0" ixz="0.0" iyy="0.001" iyz="0.0" izz="0.001"/>
    </inertial>
  </link>

  <joint name="l_move_connector_joint" type="fixed">
    <parent link="l_move_link"/>
    <child link="l_move_connector_link"/>
    <origin rpy="0.0 0.0 0" xyz="0.1205 0.0 0.01975"/>
    <axis xyz="0 1 0"/>
  </joint>

  <link name="l_move_connector_link">
    <visual>
      <geometry>
        <mesh filename="meshes/visual/MoveConnectorL.obj"/>
      </geometry>
     </visual>
    <collision>
      <geometry>
        <mesh filename="meshes/collision/MoveConnectorL.stl"/>
      </geometry>
      <origin rpy="-1.570796325 0 0" xyz="0.0 0.0 0.0"/>
    </collision>
    <!--inaccurate-->
    <inertial>
      <mass value="0.01"/>
      <origin rpy="0 0 0" xyz="0.0 0.0 0.0"/>
      <inertia ixx="0.001" ixy="0.0" ixz="0.0" iyy="0.001" iyz="0.0" izz="0.001"/>
    </inertial>
  </link>

  <joint name="l_move_sensor_joint" type="fixed">
    <parent link="l_move_connector_link"/>
    <child link="l_move_sensor_link"/>
    <origin rpy="0.0 0.0 0" xyz="0.0045 0.0 -0.00375"/>
    <axis xyz="0 1 0"/>
  </joint>

  <link name="l_move_sensor_link">
    <visual>
      <geometry>
        <mesh filename="meshes/visual/MoveSensorL_fixed.obj"/>
      </geometry>
     </visual>
    <collision>
      <geometry>
        <mesh filename="meshes/collision/MoveSensorL.stl"/>
      </geometry>
      <origin rpy="-1.570796325 0 0" xyz="0.0 0.0 0.0"/>
    </collision>
    <!--inaccurate-->
    <inertial>
      <mass value="0.01"/>
      <origin rpy="0 0 0" xyz="0.0 0.0 0.0"/>
      <inertia ixx="0.001" ixy="0.0" ixz="0.0" iyy="0.001" iyz="0.0" izz="0.001"/>
    </inertial>
  </link>

  <joint name="l_move_finger_joint" type="fixed">
    <parent link="l_move_sensor_link"/>
    <child link="l_move_finger_link"/>
    <origin rpy="0.0 0.0 0" xyz="0.023 0.0 0.0"/>
    <axis xyz="0 1 0"/>
  </joint>

  <link name="l_move_finger_link">
    <visual>
      <geometry>
        <mesh filename="meshes/visual/MoveFingerL_fixed.obj"/>
      </geometry>
     </visual>
    <collision>
      <geometry>
        <mesh filename="meshes/collision/MoveFingerL.stl"/>
      </geometry>
      <origin rpy="-1.570796325 0 0" xyz="0.0 0.0 0.0"/>
    </collision>
    <!--inaccurate-->
    <inertial>
      <mass value="0.01"/>
      <origin rpy="0 0 0" xyz="0.0 0.0 0.0"/>
      <inertia ixx="0.001" ixy="0.0" ixz="0.0" iyy="0.001" iyz="0.0" izz="0.001"/>
    </inertial>
  </link>

  <!-- =============================== -->
  <!-- |          RIGHT ARM          | -->
  <!-- =============================== -->
  <joint name="body_joint" type="fixed">
    <parent link="body_link"/>
    <child link="r_base_link"/>
    <origin rpy="0.0 0.785398163397 1.570796325" xyz="-0.2 0.93 0"/>
  </joint>

  <link name="r_base_link">
    <visual>
      <geometry>
        <mesh filename="meshes/visual/Base.obj"/>
      </geometry>
     </visual>
    <collision>
      <geometry>
        <mesh filename="meshes/collision/Base.stl"/>
      </geometry>
      <origin rpy="-1.570796325 0 0" xyz="0.0 0.0 0.0"/>
    </collision>
    <inertial>
      <mass value="4.0"/>
      <origin rpy="0 0 0" xyz="0.0 0.0 0.0"/>
      <inertia ixx="0.00443333156" ixy="0.0" ixz="0.0" iyy="0.00443333156" iyz="0.0" izz="0.0072"/>
    </inertial>
  </link>

  <joint name="r_shoulder_pan_joint" type="revolute">
    <parent link="r_base_link"/>
    <child link="r_shoulder_link"/>
    <origin rpy="0.0 0.0 0.0" xyz="0.0 0.089159 0"/>
    <axis xyz="0 1 0"/>
    <limit effort="150.0" lower="-3.14159265" upper="3.14159265" velocity="3.15"/>
    <dynamics damping="0.0" friction="0.0"/>
  </joint>

  <link name="r_shoulder_link">
    <visual>
      <geometry>
        <mesh filename="meshes/visual/Shoulder.obj"/>
      </geometry>
     </visual>
    <collision>
      <geometry>
        <mesh filename="meshes/collision/Shoulder.stl"/>
      </geometry>
      <origin rpy="-1.570796325 0 0" xyz="0.0 0.0 0.0"/>
    </collision>
    <inertial>
      <mass value="3.7"/>
      <origin rpy="0 0 0" xyz="0.0 0.0 0.0"/>
      <inertia ixx="0.010267495893" ixy="0.0" ixz="0.0" iyy="0.010267495893" iyz="0.0" izz="0.00666"/>
    </inertial>
  </link>

  <joint name="r_shoulder_lift_joint" type="revolute">
    <parent link="r_shoulder_link"/>
    <child link="r_upper_arm_link"/>
    <origin rpy="0.0 0 -1.570796325" xyz="0 0 -0.13585"/>
    <axis xyz="0 0 -1"/>
    <limit effort="150.0" lower="-3.14159265" upper="3.14159265" velocity="3.15"/>
    <dynamics damping="0.0" friction="0.0"/>
  </joint>

  <link name="r_upper_arm_link">
    <visual>
      <geometry>
        <mesh filename="meshes/visual/UpperArm.obj"/>
      </geometry>
     </visual>
    <collision>
      <geometry>
        <mesh filename="meshes/collision/UpperArm.stl"/>
      </geometry>
      <origin rpy="-1.570796325 0 0" xyz="0.0 0.0 0.0"/>
    </collision>
    <inertial>
      <mass value="8.393"/>
      <origin rpy="0 0 0" xyz="0.0 0.0 0.28"/>
      <inertia ixx="0.22689067591" ixy="0.0" ixz="0.0" iyy="0.22689067591" iyz="0.0" izz="0.0151074"/>
    </inertial>
  </link>
  
  <joint name="r_elbow_joint" type="revolute">
    <parent link="r_upper_arm_link"/>
    <child link="r_forearm_link"/>
    <origin rpy="0.0 0.0 0.0" xyz="0 0.425 0.1197"/>
    <axis xyz="0 0 -1"/>
    <!-- <limit effort="150.0" lower="-3.14159265" upper="3.14159265" velocity="3.15"/> -->
    <limit effort="150.0" lower="-3.14159265" upper="0" velocity="3.15"/>
    <dynamics damping="0.0" friction="0.0"/>
  </joint>

  <link name="r_forearm_link">
    <visual>
      <geometry>
        <mesh filename="meshes/visual/ForeArm.obj"/>
      </geometry>
     </visual>
    <collision>
      <geometry>
        <mesh filename="meshes/collision/ForeArm.stl"/>
      </geometry>
      <origin rpy="-1.570796325 0 0" xyz="0.0 0.0 0.0"/>
    </collision>
    <inertial>
      <mass value="2.275"/>
      <origin rpy="0 0 0" xyz="0.0 0.0 0.25"/>
      <inertia ixx="0.049443313556" ixy="0.0" ixz="0.0" iyy="0.049443313556" iyz="0.0" izz="0.004095"/>
    </inertial>
  </link>

  <joint name="r_wrist_1_joint" type="revolute">
    <parent link="r_forearm_link"/>
    <child link="r_wrist_1_link"/>
    <origin rpy="0.0 0.0 -1.570796325" xyz="0.0 0.39225 0.0"/>
    <axis xyz="0 0 -1"/>
    <limit effort="28.0" lower="-3.14159265" upper="3.14159265" velocity="3.2"/>
    <dynamics damping="0.0" friction="0.0"/>
  </joint>

  <link name="r_wrist_1_link">
    <visual>
      <geometry>
        <mesh filename="meshes/visual/Wrist1.obj"/>
      </geometry>
     </visual>
    <collision>
      <geometry>
        <mesh filename="meshes/collision/Wrist1.stl"/>
      </geometry>
      <origin rpy="-1.570796325 0 0" xyz="0.0 0.0 0.0"/>
    </collision>
    <inertial>
      <mass value="1.219"/>
      <origin rpy="0 0 0" xyz="0.0 0.0 0.0"/>
      <inertia ixx="0.111172755531" ixy="0.0" ixz="0.0" iyy="0.111172755531" iyz="0.0" izz="0.21942"/>
    </inertial>
  </link>

  <joint name="r_wrist_2_joint" type="revolute">
    <parent link="r_wrist_1_link"/>
    <child link="r_wrist_2_link"/>
    <origin rpy="0.0 0.0 0.0" xyz="0.0 0.0 -0.093"/>
    <axis xyz="0 1 0"/>
    <limit effort="28.0" lower="-3.14159265" upper="3.14159265" velocity="3.2"/>
    <dynamics damping="0.0" friction="0.0"/>
  </joint>

  <link name="r_wrist_2_link">
    <visual>
      <geometry>
        <mesh filename="meshes/visual/Wrist2.obj"/>
      </geometry>
     </visual>
    <collision>
      <geometry>
        <mesh filename="meshes/collision/Wrist2.stl"/>
      </geometry>
      <origin rpy="-1.570796325 0 0" xyz="0.0 0.0 0.0"/>
    </collision>
    <inertial>
      <mass value="1.219"/>
      <origin rpy="0 0 0" xyz="0.0 0.0 0.0"/>
      <inertia ixx="0.111172755531" ixy="0.0" ixz="0.0" iyy="0.111172755531" iyz="0.0" izz="0.21942"/>
    </inertial>
  </link>

  <joint name="r_wrist_3_joint" type="revolute">
    <parent link="r_wrist_2_link"/>
    <child link="r_wrist_3_link"/>
    <origin rpy="0.0 0.0 0.0" xyz="0.0 0.09465 0"/>
    <axis xyz="0 0 -1"/>
    <limit effort="28.0" lower="-3.14159265" upper="3.14159265" velocity="3.2"/>
    <dynamics damping="0.0" friction="0.0"/>
  </joint>

  <link name="r_wrist_3_link">
    <visual>
      <geometry>
        <mesh filename="meshes/visual/Wrist3.obj"/>
      </geometry>
     </visual>
    <collision>
      <geometry>
        <mesh filename="meshes/collision/Wrist3.stl"/>
      </geometry>
      <origin rpy="-1.570796325 0 0" xyz="0.0 0.0 0.0"/>
    </collision>
    <inertial>
      <mass value="0.1879"/>
      <origin rpy="0 0 0" xyz="0.0 0.0 0.0"/>
      <inertia ixx="0.0171364731454" ixy="0.0" ixz="0.0" iyy="0.0171364731454" iyz="0.0" izz="0.033822"/>
    </inertial>
  </link>

  <joint name="r_fixed_joint" type="fixed">
    <parent link="r_wrist_3_link"/>
    <child link="r_fixed_link"/>
    <origin rpy="3.1415926585 1.570796325 3.1415926585" xyz="0.0 0 -0.0823"/>
  </joint>

  <link name="r_fixed_link">
    <visual>
      <geometry>
        <mesh filename="meshes/visual/FixedR_fixed.obj"/>
      </geometry>
     </visual>
    <collision>
      <geometry>
        <mesh filename="meshes/collision/FixedR.stl"/>
      </geometry>
      <origin rpy="-1.570796325 0 0" xyz="0.0 0.0 0.0"/>
    </collision>
    <inertial>
      <mass value="0.1"/>
      <origin rpy="0 0 0" xyz="0.0 0.0 0.0"/>
      <inertia ixx="0.01" ixy="0.0" ixz="0.0" iyy="0.01" iyz="0.0" izz="0.01"/>
    </inertial>
  </link>

  <joint name="r_fixed_connector_joint" type="fixed">
    <parent link="r_fixed_link"/>
    <child link="r_fixed_connector_link"/>
    <!--<origin rpy="0.0 0.0 0" xyz="0.178 -0.0405 0.0"/>-->
    -<origin rpy="0.0 0.0 0" xyz="0.173 0 -0.04150"/>
    <axis xyz="0 1 0"/>
  </joint>

  <link name="r_fixed_connector_link">
    <visual>
      <geometry>
        <mesh filename="meshes/visual/FixedConnectorR_fixed.obj"/>
      </geometry>
     </visual>
    <collision>
      <geometry>
        <mesh filename="meshes/collision/FixedConnectorR.stl"/>
      </geometry>
      <origin rpy="-1.570796325 0 0" xyz="0.0 0.0 0.0"/>
    </collision>
    <inertial>
      <mass value="0.01"/>
      <origin rpy="0 0 0" xyz="0.0 0.0 0.0"/>
      <inertia ixx="0.001" ixy="0.0" ixz="0.0" iyy="0.001" iyz="0.0" izz="0.001"/>
    </inertial>
  </link>

  <joint name="r_fixed_sensor_joint" type="fixed">
    <parent link="r_fixed_connector_link"/>
    <child link="r_fixed_sensor_link"/>
    <origin rpy="0.0 0.0 0" xyz="0.005 0 0.0010"/>
    <axis xyz="0 1 0"/>
  </joint>

  <link name="r_fixed_sensor_link">
    <visual>
      <geometry>
        <mesh filename="meshes/visual/FixedSensorR_fixed.obj"/>
      </geometry>
     </visual>
    <collision>
      <geometry>
        <mesh filename="meshes/collision/FixedSensorR.stl"/>
      </geometry>
      <origin rpy="-1.570796325 0 0" xyz="0.0 0.0 0.0"/>
    </collision>
    <inertial>
      <mass value="0.01"/>
      <origin rpy="0 0 0" xyz="0.0 0.0 0.0"/>
      <inertia ixx="0.001" ixy="0.0" ixz="0.0" iyy="0.001" iyz="0.0" izz="0.001"/>
    </inertial>
  </link>

  <joint name="r_fixed_finger_joint" type="fixed">
    <parent link="r_fixed_sensor_link"/>
    <child link="r_fixed_finger_link"/>
    <origin rpy="0.0 0.0 0" xyz="0.023 0.0 0.0"/>
    <axis xyz="0 1 0"/>
    <limit effort="28.0" lower="-3.14159265" upper="3.14159265" velocity="3.2"/>
  </joint>

  <link name="r_fixed_finger_link">
    <visual>
      <geometry>
        <mesh filename="meshes/visual/FixedFingerR.obj"/>
      </geometry>
     </visual>
    <collision>
      <geometry>
        <mesh filename="meshes/collision/FixedFingerR.stl"/>
      </geometry>
      <origin rpy="-1.570796325 0 0" xyz="0.0 0.0 0.0"/>
    </collision>
    <inertial>
      <mass value="0.01"/>
      <origin rpy="0 0 0" xyz="0.0 0.0 0.0"/>
      <inertia ixx="0.001" ixy="0.0" ixz="0.0" iyy="0.001" iyz="0.0" izz="0.001"/>
    </inertial>
  </link>

  <joint name="r_move_joint" type="revolute">
    <parent link="r_fixed_link"/>
    <child link="r_move_link"/>
    <origin rpy="0.0 0.0 0" xyz="0.053 0 0.0085"/>
    <axis xyz="0 1 0"/>
    <limit effort="28.0" lower="-3.14159265" upper="3.14159265" velocity="3.2"/>
  </joint>

  <link name="r_move_link">
    <visual>
      <geometry>
        <mesh filename="meshes/visual/MoveR_fixed.obj"/>
      </geometry>
     </visual>
    <collision>
      <geometry>
        <mesh filename="meshes/collision/MoveR.stl"/>
      </geometry>
      <origin rpy="-1.570796325 0 0" xyz="0.0 0.0 0.0"/>
    </collision>
    <inertial>
      <mass value="0.01"/>
      <origin rpy="0 0 0" xyz="0.0 0.0 0.0"/>
      <inertia ixx="0.001" ixy="0.0" ixz="0.0" iyy="0.001" iyz="0.0" izz="0.001"/>
    </inertial>
  </link>

  <joint name="r_move_connector_joint" type="fixed">
    <parent link="r_move_link"/>
    <child link="r_move_connector_link"/>
    <origin rpy="0.0 0.0 0" xyz="0.1205 0.0 -0.01975"/>
    <axis xyz="0 1 0"/>
  </joint>

  <link name="r_move_connector_link">
    <visual>
      <geometry>
        <mesh filename="meshes/visual/MoveConnectorR.obj"/>
      </geometry>
     </visual>
    <collision>
      <geometry>
        <mesh filename="meshes/collision/MoveConnectorR.stl"/>
      </geometry>
      <origin rpy="-1.570796325 0 0" xyz="0.0 0.0 0.0"/>
    </collision>
    <inertial>
      <mass value="0.01"/>
      <origin rpy="0 0 0" xyz="0.0 0.0 0.0"/>
      <inertia ixx="0.001" ixy="0.0" ixz="0.0" iyy="0.001" iyz="0.0" izz="0.001"/>
    </inertial>
  </link>

  <joint name="r_move_sensor_joint" type="fixed">
    <parent link="r_move_connector_link"/>
    <child link="r_move_sensor_link"/>
    <origin rpy="0.0 0.0 0" xyz="0.0045 0.0 0.00375"/>
    <axis xyz="0 1 0"/>
  </joint>

  <link name="r_move_sensor_link">
    <visual>
      <geometry>
        <mesh filename="meshes/visual/MoveSensorR.obj"/>
      </geometry>
    </visual>
    <collision>
      <geometry>
        <mesh filename="meshes/collision/MoveSensorR.stl"/>
      </geometry>
      <origin rpy="-1.570796325 0 0" xyz="0.0 0.0 0.0"/>
    </collision>
    <inertial>
      <mass value="0.01"/>
      <origin rpy="0 0 0" xyz="0.0 0.0 0.0"/>
      <inertia ixx="0.001" ixy="0.0" ixz="0.0" iyy="0.001" iyz="0.0" izz="0.001"/>
    </inertial>
  </link>

  <joint name="r_move_finger_joint" type="fixed">
    <parent link="r_move_sensor_link"/>
    <child link="r_move_finger_link"/>
    <origin rpy="0.0 0.0 0" xyz="0.023 0.0 0.0"/>
    <axis xyz="0 1 0"/>
  </joint>

  <link name="r_move_finger_link">
    <visual>
      <geometry>
        <mesh filename="meshes/visual/MoveFingerR_fixed.obj"/>
      </geometry>
     </visual>
    <collision>
      <geometry>
        <mesh filename="meshes/collision/MoveFingerR.stl"/>
      </geometry>
      <origin rpy="-1.570796325 0 0" xyz="0.0 0.0 0.0"/>
    </collision>
    <inertial>
      <mass value="0.01"/>
      <origin rpy="0 0 0" xyz="0.0 0.0 0.0"/>
      <inertia ixx="0.001" ixy="0.0" ixz="0.0" iyy="0.001" iyz="0.0" izz="0.001"/>
    </inertial>
  </link>
</robot>